Traceback (most recent call last):
  File "/opt/miniconda3/envs/vlxr02/lib/python3.9/site-packages/jupyter_cache/executors/utils.py", line 51, in single_nb_execution
    executenb(
  File "/opt/miniconda3/envs/vlxr02/lib/python3.9/site-packages/nbclient/client.py", line 1112, in execute
    return NotebookClient(nb=nb, resources=resources, km=km, **kwargs).execute()
  File "/opt/miniconda3/envs/vlxr02/lib/python3.9/site-packages/nbclient/util.py", line 74, in wrapped
    return just_run(coro(*args, **kwargs))
  File "/opt/miniconda3/envs/vlxr02/lib/python3.9/site-packages/nbclient/util.py", line 53, in just_run
    return loop.run_until_complete(coro)
  File "/opt/miniconda3/envs/vlxr02/lib/python3.9/asyncio/base_events.py", line 642, in run_until_complete
    return future.result()
  File "/opt/miniconda3/envs/vlxr02/lib/python3.9/site-packages/nbclient/client.py", line 553, in async_execute
    await self.async_execute_cell(
  File "/opt/miniconda3/envs/vlxr02/lib/python3.9/site-packages/nbclient/client.py", line 857, in async_execute_cell
    self._check_raise_for_error(cell, exec_reply)
  File "/opt/miniconda3/envs/vlxr02/lib/python3.9/site-packages/nbclient/client.py", line 760, in _check_raise_for_error
    raise CellExecutionError.from_cell_and_msg(cell, exec_reply_content)
nbclient.exceptions.CellExecutionError: An error occurred while executing the following cell:
------------------
import py3Dmol as p3d

h2o_xyz = """3
water                                                                                                                          
O    0.000000000000        0.000000000000        0.000000000000                       
H    0.740848095288        0.582094932012        0.000000000000                         
H   -0.740848095288        0.582094932012        0.000000000000
"""

v = p3d.view(width=200, height=200)

v.addModel(h2o_xyz, "xyz")
v.setStyle({'stick':{}})
v.show()
------------------

[0;31m---------------------------------------------------------------------------[0m
[0;31mModuleNotFoundError[0m                       Traceback (most recent call last)
[0;32m<ipython-input-1-630db6e58b01>[0m in [0;36m<module>[0;34m[0m
[0;32m----> 1[0;31m [0;32mimport[0m [0mpy3Dmol[0m [0;32mas[0m [0mp3d[0m[0;34m[0m[0;34m[0m[0m
[0m[1;32m      2[0m [0;34m[0m[0m
[1;32m      3[0m h2o_xyz = """3
[1;32m      4[0m [0mwater[0m[0;34m[0m[0;34m[0m[0m
[1;32m      5[0m [0mO[0m    [0;36m0.000000000000[0m        [0;36m0.000000000000[0m        [0;36m0.000000000000[0m[0;34m[0m[0;34m[0m[0m

[0;31mModuleNotFoundError[0m: No module named 'py3Dmol'
ModuleNotFoundError: No module named 'py3Dmol'

